<?xml version="1.0"?>
<robot xmlns:xacro="http://ros.org/wiki/xacro">
  <xacro:macro name="abb_irb4600_60_205" params="prefix">
    <!-- link list -->
    <link name="${prefix}base_link">
      <collision name="collision">
        <geometry>
          <mesh filename="package://abb_irb4600_support/meshes/irb4600/collision/base_link.stl"/>
        </geometry>
      </collision>
      <visual name="visual">
        <geometry>
          <mesh filename="package://abb_irb4600_support/meshes/irb4600/visual/base_link.dae"/>
        </geometry>
        <material name="yellow">
          <color rgba="1 1 0 1"/>
        </material>
      </visual>
    </link>
    <link name="${prefix}link_1">
      <collision name="collision">
        <geometry>
          <mesh filename="package://abb_irb4600_support/meshes/irb4600/collision/link_1.stl"/>
        </geometry>
      </collision>
      <visual name="visual">
        <geometry>
          <mesh filename="package://abb_irb4600_support/meshes/irb4600/visual/link_1.dae"/>
        </geometry>
        <material name="yellow"/>
      </visual>
    </link>
    <link name="${prefix}link_2">
      <collision name="collision">
        <geometry>
          <mesh filename="package://abb_irb4600_support/meshes/irb4600_60_205/collision/link_2.stl"/>
        </geometry>
      </collision>
      <visual name="visual">
        <geometry>
          <mesh filename="package://abb_irb4600_support/meshes/irb4600_60_205/visual/link_2.dae"/>
        </geometry>
        <material name="yellow"/>
      </visual>
    </link>
    <link name="${prefix}link_3">
      <collision name="collision">
        <geometry>
          <mesh filename="package://abb_irb4600_support/meshes/irb4600_60_205/collision/link_3.stl"/>
        </geometry>
      </collision>
      <visual name="visual">
        <geometry>
          <mesh filename="package://abb_irb4600_support/meshes/irb4600_60_205/visual/link_3.dae"/>
        </geometry>
        <material name="yellow"/>
      </visual>
    </link>
    <link name="${prefix}link_4">
      <collision name="collision">
        <geometry>
          <mesh filename="package://abb_irb4600_support/meshes/irb4600_60_205/collision/link_4.stl"/>
        </geometry>
      </collision>
      <visual name="visual">
        <geometry>
          <mesh filename="package://abb_irb4600_support/meshes/irb4600_60_205/visual/link_4.dae"/>
        </geometry>
        <material name="yellow"/>
      </visual>
    </link>
    <link name="${prefix}link_5">
      <collision name="collision">
        <geometry>
          <mesh filename="package://abb_irb4600_support/meshes/irb4600_60_205/collision/link_5.stl"/>
        </geometry>
      </collision>
      <visual name="visual">
        <geometry>
          <mesh filename="package://abb_irb4600_support/meshes/irb4600_60_205/visual/link_5.dae"/>
        </geometry>
        <material name="yellow"/>
      </visual>
    </link>
    <link name="${prefix}link_6">
      <collision name="collision">
        <geometry>
          <mesh filename="package://abb_irb4600_support/meshes/irb4600_60_205/collision/link_6.stl"/>
        </geometry>
      </collision>
      <visual name="visual">
        <geometry>
          <mesh filename="package://abb_irb4600_support/meshes/irb4600_60_205/visual/link_6.dae"/>
        </geometry>
        <material name="yellow"/>
      </visual>
    </link>
    <!-- end of link list -->

    <!-- joint list -->
    <joint type="revolute" name="${prefix}joint_1">
      <origin xyz="0 0 0.495" rpy="0 0 0"/>
      <axis xyz="0 0 1"/>
      <parent link="${prefix}base_link"/>
      <child link="${prefix}link_1"/>
      <limit effort="0" lower="-3.141" upper="3.141" velocity="3.054"/>
    </joint>
    <joint type="revolute" name="${prefix}joint_2">
      <origin xyz="0.175 0 0" rpy="0 0 0"/>
      <axis xyz="0 1 0"/>
      <parent link="${prefix}link_1"/>
      <child link="${prefix}link_2"/>
      <limit effort="0" lower="-1.570" upper="2.617" velocity="3.054"/>
    </joint>
    <joint type="revolute" name="${prefix}joint_3">
      <origin xyz="0 0 0.9" rpy="0 0 0"/>
      <axis xyz="0 1 0"/>
      <parent link="${prefix}link_2"/>
      <child link="${prefix}link_3"/>
      <limit effort="0" lower="-3.141" upper="1.308" velocity="3.054"/>
    </joint>
    <joint type="revolute" name="${prefix}joint_4">
      <origin xyz="0 0 0.175" rpy="0 0 0"/>
      <axis xyz="1 0 0"/>
      <parent link="${prefix}link_3"/>
      <child link="${prefix}link_4"/>
      <limit effort="0" lower="-6.981" upper="6.981" velocity="4.363"/>
    </joint>
    <joint type="revolute" name="${prefix}joint_5">
      <origin xyz="0.960 0 0 " rpy="0 0 0"/>
      <axis xyz="0 1 0"/>
      <parent link="${prefix}link_4"/>
      <child link="${prefix}link_5"/>
      <limit effort="0" lower="-2.181" upper="2.094" velocity="4.363"/>
    </joint>
    <joint type="revolute" name="${prefix}joint_6">
      <origin xyz="0.135 0 0 " rpy="0 0 0"/>
      <axis xyz="1 0 0"/>
      <parent link="${prefix}link_5"/>
      <child link="${prefix}link_6"/>
      <limit effort="0" lower="-6.981" upper="6.981" velocity="6.283"/>
    </joint>
    <!-- end of joint list -->

    <!-- ROS-Industrial 'base' frame: base_link to ABB World Coordinates transform -->
    <link name="${prefix}base" />
    <joint name="${prefix}base_link-base" type="fixed">
      <origin xyz="0 0 0" rpy="0 0 0"/>
      <parent link="${prefix}base_link"/>
      <child link="${prefix}base"/>
    </joint>

    <!-- ROS-Industrial 'flange' frame: attachment point for EEF models -->
    <link name="${prefix}flange"/>
    <joint type="fixed" name="${prefix}joint_6-flange">
      <origin xyz="0 0 0" rpy="0 0 0"/>
      <parent link="${prefix}link_6"/>
      <child link="${prefix}flange"/>
    </joint>

    <!-- ROS-Industrial 'tool0' frame: all-zeros tool frame -->
    <link name="${prefix}tool0" />
    <joint name="${prefix}link_6-tool0" type="fixed">
      <origin xyz="0 0 0" rpy="0 ${radians(90)} 0" />
      <parent link="${prefix}flange" />
      <child link="${prefix}tool0" />
    </joint>
  </xacro:macro>
</robot>
