<?xml version="1.0"?>
<robot xmlns:xacro="http://ros.org/wiki/xacro">
<xacro:include filename="$(find abb_resources)/urdf/common_materials.xacro"/>

  <xacro:macro name="abb_irb4600_20_250" params="prefix">
    <!-- link list -->
    <link name="${prefix}base_link">
      <collision name="collision">
        <geometry>
          <mesh filename="package://abb_irb4600_support/meshes/irb4600_common/collision/base_link.stl"/>
        </geometry>
        <xacro:material_abb_white/>
      </collision>
      <visual name="visual">
        <geometry>
          <mesh filename="package://abb_irb4600_support/meshes/irb4600_common/visual/base_link.dae"/>
        </geometry>
        <xacro:material_abb_white/>
        <material name="yellow">
          <color rgba="1 1 0 1"/>
        </material>
      </visual>
    </link>
    <link name="${prefix}link_1">
      <collision name="collision">
        <geometry>
          <mesh filename="package://abb_irb4600_support/meshes/irb4600_common/collision/link_1.stl"/>
        </geometry>
        <xacro:material_abb_white/>
      </collision>
      <visual name="visual">
        <geometry>
          <mesh filename="package://abb_irb4600_support/meshes/irb4600_common/visual/link_1.dae"/>
        </geometry>
        <xacro:material_abb_white/>
        <material name="yellow"/>
      </visual>
    </link>
    <link name="${prefix}link_2">
      <collision name="collision">
        <geometry>
          <mesh filename="package://abb_irb4600_support/meshes/irb4600_20_250/collision/link_2.stl"/>
        </geometry>
        <xacro:material_abb_white/>
      </collision>
      <visual name="visual">
        <geometry>
          <mesh filename="package://abb_irb4600_support/meshes/irb4600_20_250/visual/link_2.dae"/>
        </geometry>
        <xacro:material_abb_white/>
        <material name="yellow"/>
      </visual>
    </link>
    <link name="${prefix}link_3">
      <collision name="collision">
        <geometry>
          <mesh filename="package://abb_irb4600_support/meshes/irb4600_20_250/collision/link_3.stl"/>
        </geometry>
        <xacro:material_abb_white/>
      </collision>
      <visual name="visual">
        <geometry>
          <mesh filename="package://abb_irb4600_support/meshes/irb4600_20_250/visual/link_3.dae"/>
        </geometry>
        <xacro:material_abb_white/>
        <material name="yellow"/>
      </visual>
    </link>
    <link name="${prefix}link_4">
      <collision name="collision">
        <geometry>
          <mesh filename="package://abb_irb4600_support/meshes/irb4600_20_250/collision/link_4.stl"/>
        </geometry>
        <xacro:material_abb_white/>
      </collision>
      <visual name="visual">
        <geometry>
          <mesh filename="package://abb_irb4600_support/meshes/irb4600_20_250/visual/link_4.dae"/>
        </geometry>
        <xacro:material_abb_white/>
        <material name="yellow"/>
      </visual>
    </link>
    <link name="${prefix}link_5">
      <collision name="collision">
        <geometry>
          <mesh filename="package://abb_irb4600_support/meshes/irb4600_20_250/collision/link_5.stl"/>
        </geometry>
        <xacro:material_abb_white/>
      </collision>
      <visual name="visual">
        <geometry>
          <mesh filename="package://abb_irb4600_support/meshes/irb4600_20_250/visual/link_5.dae"/>
        </geometry>
        <xacro:material_abb_white/>
        <material name="yellow"/>
      </visual>
    </link>
    <link name="${prefix}link_6">
      <collision name="collision">
        <geometry>
          <mesh filename="package://abb_irb4600_support/meshes/irb4600_20_250/collision/link_6.stl"/>
        </geometry>
        <xacro:material_abb_white/>
      </collision>
      <visual name="visual">
        <geometry>
          <mesh filename="package://abb_irb4600_support/meshes/irb4600_20_250/visual/link_6.dae"/>
        </geometry>
        <xacro:material_abb_white/>
        <material name="yellow"/>
      </visual>
    </link>
    <link name="${prefix}tool0"/>
    <!-- end of link list -->

    <!-- joint list -->
    <joint type="revolute" name="${prefix}joint_1">
      <origin xyz="0 0 0.495" rpy="0 0 0"/>
      <axis xyz="0 0 1"/>
      <parent link="${prefix}base_link"/>
      <child link="${prefix}link_1"/>
      <limit effort="0" lower="${radians(-180)}" upper="${radians(180)}" velocity="3.054"/>
    </joint>
    <joint type="revolute" name="${prefix}joint_2">
      <origin xyz="0.175 0 0" rpy="0 0 0"/>
      <axis xyz="0 1 0"/>
      <parent link="${prefix}link_1"/>
      <child link="${prefix}link_2"/>
      <limit effort="0" lower="${radians(-90)}" upper="${radians(150)}" velocity="3.054"/>
    </joint>
    <joint type="revolute" name="${prefix}joint_3">
      <origin xyz="0 0 1.095" rpy="0 0 0"/>
      <axis xyz="0 1 0"/>
      <parent link="${prefix}link_2"/>
      <child link="${prefix}link_3"/>
      <limit effort="0" lower="${radians(-180)}" upper="${radians(75)}" velocity="3.054"/>
    </joint>
    <joint type="revolute" name="${prefix}joint_4">
      <origin xyz="0.33 0 0.175" rpy="0 0 0"/>
      <axis xyz="1 0 0"/>
      <parent link="${prefix}link_3"/>
      <child link="${prefix}link_4"/>
      <limit effort="0" lower="${radians(-400)}" upper="${radians(400)}" velocity="4.363"/>
    </joint>
    <joint type="revolute" name="${prefix}joint_5">
      <origin xyz="0.900 0 0 " rpy="0 0 0"/>
      <axis xyz="0 1 0"/>
      <parent link="${prefix}link_4"/>
      <child link="${prefix}link_5"/>
      <limit effort="0" lower="${radians(-125)}" upper="${radians(120)}" velocity="4.363"/>
    </joint>
    <joint type="revolute" name="${prefix}joint_6">
      <origin xyz="0.085 0 0 " rpy="0 0 0"/>
      <axis xyz="1 0 0"/>
      <parent link="${prefix}link_5"/>
      <child link="${prefix}link_6"/>
      <limit effort="0" lower="${radians(-400)}" upper="${radians(400)}" velocity="6.283"/>
    </joint>
    <joint type="fixed" name="${prefix}joint_6-tool0">
      <parent link="${prefix}link_6"/>
      <child link="${prefix}tool0"/>
      <origin xyz="0 0 0" rpy="0 ${pi/2.0} 0"/>
    </joint>
    <!-- end of joint list -->

    <!-- ROS base_link to ABB World Coordinates transform -->
    <link name="${prefix}base" />
    <joint name="${prefix}base_link-base" type="fixed">
      <origin xyz="0 0 0" rpy="0 0 0"/>
      <parent link="${prefix}base_link"/>
      <child link="${prefix}base"/>
    </joint>
  </xacro:macro>
</robot>
