<?xml version="1.0"?>
<robot xmlns:xacro="http://ros.org/wiki/xacro">
  <xacro:include filename="$(find abb_resources)/urdf/common_materials.xacro"/>

  <!-- inertial values are copied from irb120_3_58 and are therefore not accurate,
       use at your own risk! -->
  <xacro:macro name="abb_irb1200_5_90" params="prefix">
    <!-- link list -->
    <link name="${prefix}base_link">
      <inertial>
        <mass value="6.215"/>
        <origin xyz="-0.04204 8.01E-05 0.07964" rpy="0 0 0"/>
        <inertia ixx="0.0247272" ixy="-8.0784E-05" ixz="0.00130902" iyy="0.0491285" iyz="-8.0419E-06" izz="0.0472376"/>
      </inertial>
      <collision name="collision">
        <geometry>
          <mesh filename="package://abb_irb1200_support/meshes/irb1200_5_90/collision/base_link.stl"/>
        </geometry>
      </collision>
      <visual name="visual">
        <geometry>
          <mesh filename="package://abb_irb1200_support/meshes/irb1200_5_90/visual/base_link.dae"/>
        </geometry>
        <xacro:material_abb_yellow />
      </visual>
    </link>
    <link name="${prefix}link_1">
      <inertial>
        <mass value="3.067" />
        <origin xyz="9.77E-05 -0.00012 0.23841" rpy="0 0 0"/>
        <inertia ixx="0.0142175" ixy="-1.28579E-05" ixz="-2.31364E-05" iyy="0.0144041" iyz="1.93404E-05" izz="0.0104533"/>
      </inertial>
      <collision name="collision">
        <geometry>
          <mesh filename="package://abb_irb1200_support/meshes/irb1200_5_90/collision/link_1.stl"/>
        </geometry>
      </collision>
      <visual name="visual">
        <geometry>
          <mesh filename="package://abb_irb1200_support/meshes/irb1200_5_90/visual/link_1.dae"/>
        </geometry>
        <xacro:material_abb_yellow />
      </visual>
    </link>
    <link name="${prefix}link_2">
      <inertial>
        <mass value="3.909"/>
        <origin xyz="0.00078 -0.00212 0.10124" rpy="0 0 0"/>
        <inertia ixx="0.0603111" ixy="9.83431E-06" ixz="5.72407E-05" iyy="0.041569" iyz="-0.00050497" izz="0.0259548"/>
      </inertial>
      <collision name="collision">
        <geometry>
          <mesh filename="package://abb_irb1200_support/meshes/irb1200_5_90/collision/link_2.stl"/>
        </geometry>
      </collision>
      <visual name="visual">
        <geometry>
          <mesh filename="package://abb_irb1200_support/meshes/irb1200_5_90/visual/link_2.dae"/>
        </geometry>
        <xacro:material_abb_yellow />
      </visual>
    </link>
    <link name="${prefix}link_3">
      <inertial>
        <mass value="2.944"/>
        <origin xyz="0.02281 0.00106 0.05791" rpy="0 0 0"/>
        <inertia ixx="0.00835606" ixy="-8.01545E-05" ixz="0.00142884" iyy="0.016713" iyz="-0.000182227" izz="0.0126984"/>
      </inertial>
      <collision name="collision">
        <geometry>
          <mesh filename="package://abb_irb1200_support/meshes/irb1200_5_90/collision/link_3.stl"/>
        </geometry>
      </collision>
      <visual name="visual">
        <geometry>
          <mesh filename="package://abb_irb1200_support/meshes/irb1200_5_90/visual/link_3.dae"/>
        </geometry>
        <xacro:material_abb_yellow />
      </visual>
    </link>
    <link name="${prefix}link_4">
      <inertial>
        <mass value="1.328"/>
        <origin xyz="0.2247 0.00015 0.00041" rpy="0 0 0"/>
        <inertia ixx="0.00284661" ixy="-2.12765E-05" ixz="-1.6435E-05" iyy="0.00401346" iyz="1.31336E-05" izz="0.0052535"/>
      </inertial>
      <collision name="collision">
        <geometry>
          <mesh filename="package://abb_irb1200_support/meshes/irb1200_5_90/collision/link_4.stl"/>
        </geometry>
      </collision>
      <visual name="visual">
        <geometry>
          <mesh filename="package://abb_irb1200_support/meshes/irb1200_5_90/visual/link_4.dae"/>
        </geometry>
        <xacro:material_abb_yellow />
      </visual>
    </link>
    <link name="${prefix}link_5">
      <inertial>
        <mass value="0.546"/>
        <origin xyz="-0.00109 3.68E-05 6.22E-05" rpy="0 0 0"/>
        <inertia ixx="0.000404891" ixy="1.61943E-06" ixz="8.46805E-07" iyy="0.000892825" iyz="-1.51792E-08" izz="0.000815468"/>
      </inertial>
      <collision name="collision">
        <geometry>
          <mesh filename="package://abb_irb1200_support/meshes/irb1200_5_90/collision/link_5.stl"/>
        </geometry>
      </collision>
      <visual name="visual">
        <geometry>
          <mesh filename="package://abb_irb1200_support/meshes/irb1200_5_90/visual/link_5.dae"/>
        </geometry>
        <xacro:material_abb_yellow />
      </visual>
    </link>
    <link name="${prefix}link_6">
      <inertial>
        <mass value="0.137"/>
        <origin xyz="-0.00706 -0.00017 -1.32E-06" rpy="0 0 0"/>
        <inertia ixx="0.001" ixy="0" ixz="0" iyy="0.001" iyz="0" izz="0.001"/>
      </inertial>
      <collision name="collision">
        <geometry>
          <mesh filename="package://abb_irb1200_support/meshes/irb1200_5_90/collision/link_6.stl"/>
        </geometry>
      </collision>
      <visual name="visual">
        <geometry>
          <mesh filename="package://abb_irb1200_support/meshes/irb1200_5_90/visual/link_6.dae"/>
        </geometry>
        <xacro:material_abb_yellow />
      </visual>
    </link>
    <link name="${prefix}tool0"/>
    <!-- end of link list -->

    <!-- joint list -->
    <joint type="revolute" name="${prefix}joint_1">
      <origin xyz="0 0 0.3991" rpy="0 0 0"/>
      <axis xyz="0 0 1"/>
      <parent link="${prefix}base_link"/>
      <child link="${prefix}link_1"/>
      <limit effort="0" lower="-2.967" upper="2.967" velocity="5.027"/>
    </joint>
    <joint type="revolute" name="${prefix}joint_2">
      <origin xyz="0 0 0" rpy="0 0 0"/>
      <axis xyz="0 1 0"/>
      <parent link="${prefix}link_1"/>
      <child link="${prefix}link_2"/>
      <limit effort="0" lower="-1.745" upper="2.269" velocity="4.189"/>
    </joint>
    <joint type="revolute" name="${prefix}joint_3">
      <origin xyz="0 0 0.448" rpy="0 0 0"/>
      <axis xyz="0 1 0"/>
      <parent link="${prefix}link_2"/>
      <child link="${prefix}link_3"/>
      <limit effort="0" lower="-3.491" upper="1.222" velocity="5.236"/>
    </joint>
    <joint type="revolute" name="${prefix}joint_4">
      <origin xyz="0 0 0.042" rpy="0 0 0"/>
      <axis xyz="1 0 0"/>
      <parent link="${prefix}link_3"/>
      <child link="${prefix}link_4"/>
      <limit effort="0" lower="-4.712" upper="4.712" velocity="6.981"/>
    </joint>
    <joint type="revolute" name="${prefix}joint_5">
      <origin xyz="0.451 0 0" rpy="0 0 0"/>
      <axis xyz="0 1 0"/>
      <parent link="${prefix}link_4"/>
      <child link="${prefix}link_5"/>
      <limit effort="0" lower="-2.269" upper="2.269" velocity="7.069"/>
    </joint>
    <joint type="revolute" name="${prefix}joint_6">
      <origin xyz="0.082 0 0" rpy="0 0 0"/>
      <axis xyz="1 0 0"/>
      <parent link="${prefix}link_5"/>
      <child link="${prefix}link_6"/>
      <limit effort="0" lower="-6.283" upper="6.283" velocity="10.472"/>
    </joint>
    <joint type="fixed" name="${prefix}joint_6-tool0">
      <parent link="${prefix}link_6"/>
      <child link="${prefix}tool0"/>
      <origin xyz="0 0 0" rpy="0 ${pi/2.0} 0"/>
    </joint>
    <!-- end of joint list -->

    <!-- ROS base_link to ABB World Coordinates transform -->
    <link name="${prefix}base" />
    <joint name="${prefix}base_link-base" type="fixed">
      <origin xyz="0 0 0" rpy="0 0 0"/>
      <parent link="${prefix}base_link"/>
      <child link="${prefix}base"/>
    </joint>
  </xacro:macro>
</robot>
