<?xml version="1.0"?>
<robot xmlns:xacro="http://ros.org/wiki/xacro">
  <xacro:include filename="$(find abb_resources)/urdf/common_materials.xacro"/>

  <xacro:macro name="abb_crb15000_5_95" params="prefix">
    <!-- link list -->
    <link name="${prefix}base_link">
      <collision>
        <geometry>
          <mesh filename="package://abb_crb15000_support/meshes/crb15000_5_95/collision/base_link.stl"/>
        </geometry>
      </collision>
      <visual>
        <geometry>
          <mesh filename="package://abb_crb15000_support/meshes/crb15000_5_95/visual/base_link.stl"/>
        </geometry>
        <xacro:material_abb_dark_gray />
      </visual>
    </link>
    <link name="${prefix}link_1">
      <collision>
        <geometry>
          <mesh filename="package://abb_crb15000_support/meshes/crb15000_5_95/collision/link_1.stl"/>
        </geometry>
      </collision>
      <visual>
        <geometry>
          <mesh filename="package://abb_crb15000_support/meshes/crb15000_5_95/visual/link_1.stl"/>
        </geometry>
        <xacro:material_abb_dark_gray />
      </visual>
    </link>
    <link name="${prefix}link_2">
      <collision>
        <geometry>
          <mesh filename="package://abb_crb15000_support/meshes/crb15000_5_95/collision/link_2.stl"/>
        </geometry>
      </collision>
      <visual>
        <geometry>
          <mesh filename="package://abb_crb15000_support/meshes/crb15000_5_95/visual/link_2.stl"/>
        </geometry>
        <xacro:material_abb_dark_gray />
      </visual>
    </link>
    <link name="${prefix}link_3">
      <collision>
        <geometry>
          <mesh filename="package://abb_crb15000_support/meshes/crb15000_5_95/collision/link_3.stl"/>
        </geometry>
      </collision>
      <visual>
        <geometry>
          <mesh filename="package://abb_crb15000_support/meshes/crb15000_5_95/visual/link_3.stl"/>
        </geometry>
        <xacro:material_abb_dark_gray />
      </visual>
    </link>
    <link name="${prefix}link_4">
      <collision>
        <geometry>
          <mesh filename="package://abb_crb15000_support/meshes/crb15000_5_95/collision/link_4.stl"/>
        </geometry>
      </collision>
      <visual>
        <geometry>
          <mesh filename="package://abb_crb15000_support/meshes/crb15000_5_95/visual/link_4.stl"/>
        </geometry>
        <xacro:material_abb_graphite_white />
      </visual>
    </link>
    <link name="${prefix}link_5">
      <collision>
        <geometry>
          <mesh filename="package://abb_crb15000_support/meshes/crb15000_5_95/collision/link_5.stl"/>
        </geometry>
      </collision>
      <visual>
        <geometry>
          <mesh filename="package://abb_crb15000_support/meshes/crb15000_5_95/visual/link_5.stl"/>
        </geometry>
        <xacro:material_abb_graphite_white />
      </visual>
    </link>
    <link name="${prefix}link_6">
      <collision>
        <geometry>
          <mesh filename="package://abb_crb15000_support/meshes/crb15000_5_95/collision/link_6.stl"/>
        </geometry>
      </collision>
      <visual>
        <geometry>
          <mesh filename="package://abb_crb15000_support/meshes/crb15000_5_95/visual/link_6.stl"/>
        </geometry>
        <xacro:material_abb_gray_white />
      </visual>
    </link>
    <!-- end of link list -->

    <!-- joint list -->
    <joint type="revolute" name="${prefix}joint_1">
      <origin xyz="0 0 0.265" rpy="0 0 0"/>
      <axis xyz="0 0 1"/>
      <parent link="${prefix}base_link"/>
      <child link="${prefix}link_1"/>
      <limit effort="0" lower="${radians(-180)}" upper="${radians(180)}" velocity="${radians(125)}"/>
    </joint>
    <joint type="revolute" name="${prefix}joint_2">
      <origin xyz="0 0 0" rpy="0 0 0"/>
      <axis xyz="0 1 0"/>
      <parent link="${prefix}link_1"/>
      <child link="${prefix}link_2"/>
      <limit effort="0" lower="${radians(-180)}" upper="${radians(180)}" velocity="${radians(125)}"/>
    </joint>
    <joint type="revolute" name="${prefix}joint_3">
      <origin xyz="0 0 0.444" rpy="0 0 0"/>
      <axis xyz="0 1 0"/>
      <parent link="${prefix}link_2"/>
      <child link="${prefix}link_3"/>
      <limit effort="0" lower="${radians(-225)}" upper="${radians(85)}" velocity="${radians(140)}"/>
    </joint>
    <joint type="revolute" name="${prefix}joint_4">
      <origin xyz="0 0 0.110" rpy="0 0 0"/>
      <axis xyz="1 0 0"/>
      <parent link="${prefix}link_3"/>
      <child link="${prefix}link_4"/>
      <limit effort="0" lower="${radians(-180)}" upper="${radians(180)}" velocity="${radians(200)}"/>
    </joint>
    <joint type="revolute" name="${prefix}joint_5">
      <origin xyz="0.470 0 0" rpy="0 0 0"/>
      <axis xyz="0 1 0"/>
      <parent link="${prefix}link_4"/>
      <child link="${prefix}link_5"/>
      <limit effort="0" lower="${radians(-180)}" upper="${radians(180)}" velocity="${radians(200)}"/>
    </joint>
    <joint type="revolute" name="${prefix}joint_6">
      <origin xyz="0.101 0 0.080" rpy="0 0 0"/>
      <axis xyz="1 0 0"/>
      <parent link="${prefix}link_5"/>
      <child link="${prefix}link_6"/>
      <limit effort="0" lower="${radians(-180)}" upper="${radians(180)}" velocity="${radians(200)}"/>
    </joint>
    <!-- end of joint list -->

    <!-- ROS-Industrial 'base' frame: base_link to ABB World Coordinates transform -->
    <link name="${prefix}base" />
    <joint name="${prefix}base_link-base" type="fixed">
      <origin xyz="0 0 0" rpy="0 0 0"/>
      <parent link="${prefix}base_link"/>
      <child link="${prefix}base"/>
    </joint>

    <!-- ROS-Industrial 'flange' frame: attachment point for EEF models -->
    <link name="${prefix}flange"/>
    <joint type="fixed" name="${prefix}joint_6-flange">
      <origin xyz="0 0 0" rpy="0 0 0"/>
      <parent link="${prefix}link_6"/>
      <child link="${prefix}flange"/>
    </joint>

    <!-- ROS-Industrial 'tool0' frame: all-zeros tool frame -->
    <link name="${prefix}tool0" />
    <joint name="${prefix}flange-tool0" type="fixed">
      <origin xyz="0 0 0" rpy="0 ${radians(90)} 0" />
      <parent link="${prefix}flange" />
      <child link="${prefix}tool0" />
    </joint>
  </xacro:macro>
</robot>
